function HandleException(err, req, res, next) {
	next(err);
}